#VRML_SIM R2022b utf8

EXTERNPROTO "https://raw.githubusercontent.com/cyberbotics/webots/R2022b/projects/objects/backgrounds/protos/TexturedBackground.proto"
EXTERNPROTO "https://raw.githubusercontent.com/cyberbotics/webots/R2022b/projects/objects/backgrounds/protos/TexturedBackgroundLight.proto"
EXTERNPROTO "https://raw.githubusercontent.com/cyberbotics/webots/R2022b/projects/objects/floors/protos/CircleArena.proto"

WorldInfo {
}
Viewpoint {
  orientation 0.29747785490610734 0.36205772878321785 -0.8834144706018794 1.5050540113089346
  position -0.27258755734806916 1.0695251671743262 1.0113591046005372
}
TexturedBackground {
}
TexturedBackgroundLight {
}
CircleArena {
  radius 0.385
  floorAppearance PBRAppearance {
    baseColor 0 0 0
    roughness 1
    metalness 0
  }
  wallHeight 1e-06
  wallAppearance PBRAppearance {
    roughness 1
    metalness 0
  }
}
Robot {
  translation 0.14 0.21 0.07
  rotation 0 1 0 0
  children [
    DEF GROUND_SENSOR_DS9 DistanceSensor {
      translation 0.03 -0.06 0
      rotation 0.7062223501084638 -0.04999984414532509 -0.7062223501084638 3.14103
      children [
        Group {
          children [
            Transform {
              translation 0 -0.002 0
              children [
                Shape {
                  appearance PBRAppearance {
                    baseColor 0 0 1
                    roughness 0.4
                    metalness 0
                  }
                  geometry DEF SPHERE Sphere {
                    radius 0.0014
                  }
                }
              ]
            }
            Transform {
              translation 0 0.002 0
              children [
                Shape {
                  appearance DEF BLACK PBRAppearance {
                    baseColor 0.101961 0.101961 0.101961
                    roughness 0.45
                    metalness 0
                  }
                  geometry USE SPHERE
                }
              ]
            }
            Transform {
              translation -0.0025 0 0
              children [
                Shape {
                  appearance USE BLACK
                  geometry Box {
                    size 0.006 0.01 0.005
                  }
                }
              ]
            }
          ]
        }
      ]
      name "left line sensor"
      model "Khepera III ground sensor"
      lookupTable [
        0 4000 0
        0.0145 4000 0.01
        0.0223 3816 0.05
        0.0345 1855 0.1
        0.0516 974 0.2
        0.0774 474 0.2
        0.1145 224 0.2
        0.15 170 0.3
        0.3 0 0.3
      ]
      type "infra-red"
    }
    DEF GROUND_SENSOR_DS9 DistanceSensor {
      translation -0.03 -0.06 0
      rotation 0.7062245514764216 -0.04993761892455883 -0.7062245514764216 3.14103
      children [
        Group {
          children [
            Transform {
              translation 0 -0.002 0
              children [
                Shape {
                  appearance PBRAppearance {
                    baseColor 0 0 1
                    roughness 0.4
                    metalness 0
                  }
                  geometry DEF SPHERE Sphere {
                    radius 0.0014
                  }
                }
              ]
            }
            Transform {
              translation 0 0.002 0
              children [
                Shape {
                  appearance DEF BLACK PBRAppearance {
                    baseColor 0.101961 0.101961 0.101961
                    roughness 0.45
                    metalness 0
                  }
                  geometry USE SPHERE
                }
              ]
            }
            Transform {
              translation -0.0025 0 0
              children [
                Shape {
                  appearance USE BLACK
                  geometry Box {
                    size 0.006 0.01 0.005
                  }
                }
              ]
            }
          ]
        }
      ]
      name "right line sensor"
      model "Khepera III ground sensor"
      lookupTable [
        0 4000 0
        0.0145 4000 0.01
        0.0223 3816 0.05
        0.0345 1855 0.1
        0.0516 974 0.2
        0.0774 474 0.2
        0.1145 224 0.2
        0.15 170 0.3
        0.3 0 0.3
      ]
      type "infra-red"
    }
    DistanceSensor {
      translation -0.05 -0.05 0
      rotation 0 -0.050494873471905545 -0.9987243201970483 2.3562
      name "forward right sensor"
      lookupTable [
        0 800 0
        0.1 750 0
        0.2 700 0
        0.3 650 0
        0.4 600 0
        0.5 550 0
        0.6 0 0
      ]
    }
    DistanceSensor {
      translation 0.05 -0.05 0
      rotation 0 0.050494873471905545 0.9987243201970483 -0.7854
      name "forward left sensor"
      lookupTable [
        0 800 0
        0.1 750 0
        0.2 700 0
        0.3 650 0
        0.4 600 0
        0.5 550 0
        0.6 0 0
      ]
    }
    DistanceSensor {
      translation 0 -0.05 0
      rotation 0 0.050494873471905545 0.9987243201970483 -1.57
      name "front sensor"
      lookupTable [
        0 800 0
        0.1 750 0
        0.2 700 0
        0.3 650 0
        0.4 600 0
        0.5 550 0
        0.6 0 0
      ]
    }
    DistanceSensor {
      translation -0.05 0 0
      rotation 0 0 1 3.141592
      name "right sensor"
      lookupTable [
        0 800 0
        0.1 750 0
        0.2 700 0
        0.3 650 0
        0.4 600 0
        0.5 550 0
        0.6 0 0
      ]
    }
    DistanceSensor {
      translation 0.05 0 0
      name "left sensor"
      lookupTable [
        0 800 0
        0.1 750 0
        0.2 700 0
        0.3 650 0
        0.4 600 0
        0.5 550 0
        0.6 0 0
      ]
    }
    HingeJoint {
      jointParameters HingeJointParameters {
        position 7.679762771801518
        anchor 0.05 0.025 -0.03
      }
      device [
        RotationalMotor {
          name "right motor"
          maxVelocity 50
          maxTorque 720
        }
      ]
      endPoint Solid {
        translation 0.05 0.025 -0.03
        rotation -0.5410925142588363 -0.644130196334805 -0.5406617992633995 4.286793317246558
        children [
          DEF wheel Shape {
            appearance PBRAppearance {
              baseColor 1 1 0
              roughness 1
              metalness 0
            }
            geometry Cylinder {
              height 0.05
              radius 0.025
            }
          }
        ]
        name "left wheel"
        boundingObject USE wheel
        physics Physics {
        }
      }
    }
    HingeJoint {
      jointParameters HingeJointParameters {
        position 30.719056119620795
        anchor -0.05 0.025 -0.03
      }
      device [
        RotationalMotor {
          name "left motor"
          maxVelocity 50
          maxTorque 720
        }
      ]
      endPoint Solid {
        translation -0.05 0.025 -0.03
        rotation 0.3233438885726643 -0.8894176976481603 0.32308650363788666 4.596258913499741
        children [
          DEF wheel Shape {
            appearance PBRAppearance {
              baseColor 1 1 0
              roughness 1
              metalness 0
            }
            geometry Cylinder {
              height 0.05
              radius 0.025
            }
          }
        ]
        name "right wheel"
        boundingObject USE wheel
        physics Physics {
        }
      }
    }
    DEF body Transform {
      children [
        Shape {
          appearance PBRAppearance {
            baseColor 0 0 0
          }
          geometry Box {
            size 0.1 0.1 0.1
          }
        }
      ]
    }
  ]
  boundingObject USE body
  physics Physics {
  }
  controller "mini_sumo_robo_generico"
}
Solid {
  translation 0.01 -0.26 0.11
  children [
    Shape {
      geometry Box {
        size 0.1 0.1 0.1
      }
    }
  ]
  boundingObject Box {
    size 0.1 0.1 0.1
  }
  physics Physics {
  }
}
