#VRML_SIM R2021a utf8
WorldInfo {
  coordinateSystem "NUE"
}
Viewpoint {
  orientation 0.982548475816808 0.15451931718065332 0.10354841036004411 5.086051511243688
  position -0.1968811427173779 2.090052967893386 -0.3169407391888227
}
TexturedBackground {
}
TexturedBackgroundLight {
  castShadows FALSE
}
CircleArena {
  translation 0 0.5 -1
  radius 0.5
  floorAppearance PBRAppearance {
    baseColor 0 0 0
    roughness 1
    metalness 0
    occlusionMap ImageTexture {
      url [
        "textures/parquetry/chequered_parquetry_occlusion.jpg"
      ]
    }
  }
  wallThickness 0.03
  wallHeight 0.0001
  wallAppearance PBRAppearance {
    metalness 0
  }
}
Robot {
  translation -0.311648 0.61 -0.772947
  rotation -2.698941073254372e-08 0.7071062811861716 0.7071072811865693 3.14159
  children [
    DEF GROUND_SENSOR_DS9 DistanceSensor {
      translation 0.03 -0.06 0
      rotation 0 1 0 1.57
      children [
        Group {
          children [
            Transform {
              translation 0 -0.002 0
              children [
                Shape {
                  appearance PBRAppearance {
                    baseColor 0 0 1
                    roughness 0.4
                    metalness 0
                  }
                  geometry DEF SPHERE Sphere {
                    radius 0.0014
                  }
                }
              ]
            }
            Transform {
              translation 0 0.002 0
              children [
                Shape {
                  appearance DEF BLACK PBRAppearance {
                    baseColor 0.101961 0.101961 0.101961
                    roughness 0.45
                    metalness 0
                  }
                  geometry USE SPHERE
                }
              ]
            }
            Transform {
              translation -0.0025 0 0
              children [
                Shape {
                  appearance USE BLACK
                  geometry Box {
                    size 0.006 0.01 0.005
                  }
                }
              ]
            }
          ]
        }
      ]
      name "left line sensor"
      model "Khepera III ground sensor"
      lookupTable [
        0 4000 0
        0.0145 4000 0.01
        0.0223 3816 0.05
        0.0345 1855 0.1
        0.0516 974 0.2
        0.0774 474 0.2
        0.1145 224 0.2
        0.15 170 0.3
        0.3 0 0.3
      ]
      type "infra-red"
    }
    DEF GROUND_SENSOR_DS9 DistanceSensor {
      translation -0.03 -0.06 0
      rotation 0 1 0 1.5708
      children [
        Group {
          children [
            Transform {
              translation 0 -0.002 0
              children [
                Shape {
                  appearance PBRAppearance {
                    baseColor 0 0 1
                    roughness 0.4
                    metalness 0
                  }
                  geometry DEF SPHERE Sphere {
                    radius 0.0014
                  }
                }
              ]
            }
            Transform {
              translation 0 0.002 0
              children [
                Shape {
                  appearance DEF BLACK PBRAppearance {
                    baseColor 0.101961 0.101961 0.101961
                    roughness 0.45
                    metalness 0
                  }
                  geometry USE SPHERE
                }
              ]
            }
            Transform {
              translation -0.0025 0 0
              children [
                Shape {
                  appearance USE BLACK
                  geometry Box {
                    size 0.006 0.01 0.005
                  }
                }
              ]
            }
          ]
        }
      ]
      name "right line sensor"
      model "Khepera III ground sensor"
      lookupTable [
        0 4000 0
        0.0145 4000 0.01
        0.0223 3816 0.05
        0.0345 1855 0.1
        0.0516 974 0.2
        0.0774 474 0.2
        0.1145 224 0.2
        0.15 170 0.3
        0.3 0 0.3
      ]
      type "infra-red"
    }
    DistanceSensor {
      translation -0.05 -0.05 0
      rotation 0 -0.050494873471905545 -0.9987243201970483 2.3562
      name "forward right sensor"
      lookupTable [
        0 800 0
        0.1 750 0
        0.2 700 0
        0.3 650 0
        0.4 600 0
        0.5 550 0
        0.6 0 0
      ]
    }
    DistanceSensor {
      translation 0.05 -0.05 0
      rotation 0 0.050494873471905545 0.9987243201970483 -0.7854
      name "forward left sensor"
      lookupTable [
        0 800 0
        0.1 750 0
        0.2 700 0
        0.3 650 0
        0.4 600 0
        0.5 550 0
        0.6 0 0
      ]
    }
    DistanceSensor {
      translation 0 -0.05 0
      rotation 0 0.050494873471905545 0.9987243201970483 -1.57
      name "front sensor"
      lookupTable [
        0 800 0
        0.1 750 0
        0.2 700 0
        0.3 650 0
        0.4 600 0
        0.5 550 0
        0.6 0 0
      ]
    }
    DistanceSensor {
      translation -0.05 0 0
      rotation 0 0 1 3.141592
      name "right sensor"
      lookupTable [
        0 800 0
        0.1 750 0
        0.2 700 0
        0.3 650 0
        0.4 600 0
        0.5 550 0
        0.6 0 0
      ]
    }
    DistanceSensor {
      translation 0.05 0 0
      name "left sensor"
      lookupTable [
        0 800 0
        0.1 750 0
        0.2 700 0
        0.3 650 0
        0.4 600 0
        0.5 550 0
        0.6 0 0
      ]
    }
    HingeJoint {
      jointParameters HingeJointParameters {
        position 7.679762771801518
        anchor 0.05 0.025 -0.03
      }
      device [
        RotationalMotor {
          name "right motor"
          maxVelocity 50
          maxTorque 720
        }
      ]
      endPoint Solid {
        translation 0.05 0.025 -0.03
        rotation 4.712153956748988e-16 7.853589927914979e-17 1 1.5700000000000003
        children [
          DEF wheel Shape {
            appearance PBRAppearance {
              baseColor 1 1 0
              roughness 1
              metalness 0
            }
            geometry Cylinder {
              height 0.05
              radius 0.025
            }
          }
        ]
        name "left wheel"
        boundingObject USE wheel
        physics Physics {
        }
      }
    }
    HingeJoint {
      jointParameters HingeJointParameters {
        position 30.719056119620795
        anchor -0.05 0.025 -0.03
      }
      device [
        RotationalMotor {
          name "left motor"
          maxVelocity 50
          maxTorque 720
        }
      ]
      endPoint Solid {
        translation -0.05 0.025 -0.03
        rotation 0 -1.178038489187247e-16 1 1.57
        children [
          DEF wheel Shape {
            appearance PBRAppearance {
              baseColor 1 1 0
              roughness 1
              metalness 0
            }
            geometry Cylinder {
              height 0.05
              radius 0.025
            }
          }
        ]
        name "right wheel"
        boundingObject USE wheel
        physics Physics {
        }
      }
    }
    DEF body Transform {
      children [
        Shape {
          appearance PBRAppearance {
            baseColor 0 0 0
          }
          geometry Box {
            size 0.1 0.1 0.1
          }
        }
      ]
    }
  ]
  boundingObject USE body
  physics Physics {
  }
  controller "mini_sumo_robo_generico"
}
